Workbook
Name Slicer_PhraseDesc: #N/A
Name Timeline_Week: #N/A

Sheet Q1Pivot
A3: Sum of Unique Visits | B3: PhraseDesc
A4: WeekCode | B4: 2 - Pre-Promo | C4: 3 - Promo | D4: 4 - Post-Promo | E4: 1 - Initial Period | F4: Grand Total
A5: 1 | E5: 1509 | F5: 1509
A6: 2 | E6: 1450 | F6: 1450
A7: 3 | E7: 1306 | F7: 1306
A8: 4 | E8: 1301 | F8: 1301
A9: 5 | E9: 1255 | F9: 1255
A10: 6 | E10: 841 | F10: 841
A11: 7 | E11: 731 | F11: 731
A12: 8 | E12: 706 | F12: 706
A13: 9 | E13: 976 | F13: 976
A14: 10 | E14: 850 | F14: 850
A15: 11 | E15: 791 | F15: 791
A16: 12 | E16: 685 | F16: 685
... A18: 14 | E18: 594 | F18: 594
A19: 15 | B19: 537 | F19: 537
A20: 16 | B20: 508 | F20: 508
A21: 17 | B21: 495 | F21: 495
A22: 18 | B22: 585 | F22: 585
A23: 19 | B23: 549 | F23: 549
A24: 20 | B24: 500 | F24: 500
A25: 21 | B25: 525 | F25: 525
A26: 22 | B26: 520 | F26: 520
A27: 23 | B27: 511 | F27: 511
A28: 24 | B28: 507 | F28: 507
A29: 25 | B29: 500 | F29: 500
A30: 26 | B30: 511 | F30: 511
... A39: 35 | B39: 734 | F39: 734
A40: 36 | C40: 930 | F40: 930
A41: 37 | C41: 1136 | F41: 1136
A42: 38 | C42: 2229 | F42: 2229
A43: 39 | C43: 1946 | F43: 1946
A44: 40 | C44: 2228 | F44: 2228
A45: 41 | C45: 3617 | F45: 3617
A46: 42 | C46: 2482 | F46: 2482
A47: 43 | C47: 2896 | F47: 2896
A48: 44 | C48: 1585 | F48: 1585
A49: 45 | C49: 1689 | F49: 1689
A50: 46 | C50: 1030 | F50: 1030
A51: 47 | C51: 1166 | F51: 1166
...

Sheet Q1
A1: Prepared by (learners):
B2: Gumpal, Peter-Paul
B3: Zuñiga, Ma. Angelica Monina
B5: Unique Visits Week-on-Week (WoW)
B6: May 25 to August 29
B29: Revenue WoW
B30: May 25 to August 29
B53: Profit WoW
B54: May 25 to August 29
B78: Volume WoW
B79: May 25 to August 29

Sheet Q2
A1: Descriptive Statistics
A4: Initial Period | B4: Visits | C4: Unique Visits | D4: Revenue | E4: Profit | F4: Volume
A5: Mean | B5: 1055.2143 | C5: 975.92857 | D5: 608250.12 | E5: 200233.41 | F5: 18736.714
A6: Standard Error | B6: 94.88664 | C6: 85.415948 | D6: 41674.152 | E6: 16220.5 | F6: 1450.5282
A7: Median | B7: 899 | C7: 845.5 | D7: 586169.66 | E7: 208913 | F7: 17270
A8: Mode | B8: 1632 | C8: 1509 | D8: 890076.65 | E8: 275218.1 | F8: 28053
A9: Standard Deviation | B9: 355.0333 | C9: 319.59721 | D9: 155930.4 | E9: 60691.553 | F9: 5427.3795
A10: Sample Variance | B10: 126048.64 | C10: 102142.38 | D10: 2.4314289e+10 | E10: 3.6834646e+09 | F10: 29456448
A11: Kurtosis | B11: -1.4406592 | C11: -1.3957937 | D11: 0.50255719 | E11: 0.50365497 | F11: -0.30015322
A12: Skewness | B12: 0.54328993 | C12: 0.53717466 | D12: -0.21719204 | E12: -0.86903315 | F12: 0.21304576
A13: Range | B13: 1006 | C13: 915 | D13: 615509.04 | E13: 212637.7 | F13: 19420
A14: Minimum | B14: 626 | C14: 594 | D14: 274567.61 | E14: 62580.4 | F14: 8633
A15: Maximum | B15: 1632 | C15: 1509 | D15: 890076.65 | E15: 275218.1 | F15: 28053
A16: Sum | B16: 14773 | C16: 13663 | D16: 8515501.7 | E16: 2803267.7 | F16: 262314
... A18: Confidence Level(95%) | B18: 204.99012 | C18: 184.52994 | D18: 90031.531 | E18: 35042.259 | F18: 3133.6756
A23: Pre-Promo | B23: Visits | C23: Unique Visits | D23: Revenue | E23: Profit | F23: Volume
A24: Mean | B24: 562.95238 | C24: 516.80952 | D24: 534313.52 | E24: 159932.03 | F24: 18440.857
A25: Standard Error | B25: 17.647538 | C25: 15.48019 | D25: 32842.408 | E25: 9314.1252 | F25: 1301.8851
A26: Median | B26: 558 | C26: 510 | D26: 534541.68 | E26: 152476.4 | F26: 17215
A27: Mode | B27: 558 | C27: 511 | D27: 951216.16 | E27: 273174.7 | F27: 31972
A28: Standard Deviation | B28: 80.871179 | C28: 70.939142 | D28: 150502.82 | E28: 42682.684 | F28: 5965.9868
A29: Sample Variance | B29: 6540.1476 | C29: 5032.3619 | D29: 2.2651099e+10 | E29: 1.8218115e+09 | F29: 35592999
A30: Kurtosis | B30: 3.9301211 | C30: 4.7254532 | D30: 1.6047885 | E30: 1.0407275 | F30: -0.1383475
A31: Skewness | B31: 0.37569574 | C31: 0.79501239 | D31: 1.0069038 | E31: 1.086959 | F31: 0.57271931
A32: Range | B32: 412 | C32: 368 | D32: 635569.05 | E32: 172786.3 | F32: 22980
A33: Minimum | B33: 383 | C33: 366 | D33: 315647.11 | E33: 100388.4 | F33: 8992
A34: Maximum | B34: 795 | C34: 734 | D34: 951216.16 | E34: 273174.7 | F34: 31972
A35: Sum | B35: 11822 | C35: 10853 | D35: 11220584 | E35: 3358572.7 | F35: 387258
... A37: Confidence Level(95%) | B37: 36.812119 | C37: 32.29111 | D37: 68508.061 | E37: 19428.924 | F37: 2715.6846
A41: Promo | B41: Visits | C41: Unique Visits | D41: Revenue | E41: Profit | F41: Volume
A42: Mean | B42: 1814.3529 | C42: 1738.8235 | D42: 456398.85 | E42: 131929.9 | F42: 17112.824
A43: Standard Error | B43: 183.86666 | C43: 180.21012 | D43: 39227.979 | E43: 11587.587 | F43: 1581.1111
A44: Median | B44: 1663 | C44: 1585 | D44: 413937.08 | E44: 114328.4 | F44: 17299
A45: Mode | B45: 3726 | C45: 3617 | D45: 897163.71 | E45: 266476.7 | F45: 31496
A46: Standard Deviation | B46: 758.10165 | C46: 743.02534 | D46: 161741.1 | E46: 47776.847 | F46: 6519.0879
A47: Sample Variance | B47: 574718.12 | C47: 552086.65 | D47: 2.6160183e+10 | E47: 2.2826271e+09 | F47: 42498507
A48: Kurtosis | B48: 1.0640496 | C48: 1.0862724 | D48: 2.2535303 | E48: 2.8000506 | F48: 0.19342307
A49: Skewness | B49: 1.2069843 | C49: 1.2075731 | D49: 1.4320288 | E49: 1.5545284 | F49: 0.63987382
A50: Range | B50: 2726 | C50: 2687 | D50: 629004.2 | E50: 184635.3 | F50: 23682
A51: Minimum | B51: 1000 | C51: 930 | D51: 268159.51 | E51: 81841.4 | F51: 7814
...

Sheet Q3
A1: Prepared by (learners):
B2: Gumpal, Peter-Paul
B3: Zuñiga, Ma. Angelica Monina
B5: MEAN
A6: PhraseDesc | B6: .Visits. | C6: .Unique Visits. | D6: .Revenue. | E6: .Profit. | F6: .Volume.
A7: 1 - Initial Period | B7: 1055.2143 | C7: 975.92857 | D7: 608250.12 | E7: 200233.41 | F7: 18736.714
A8: 2 - Pre-Promo | B8: 562.95238 | C8: 516.80952 | D8: 534313.52 | E8: 159932.03 | F8: 18440.857
A9: 3 - Promo | B9: 1814.3529 | C9: 1738.8235 | D9: 456398.85 | E9: 131929.9 | F9: 17112.824
A10: 4 - Post-Promo | B10: 856.57143 | C10: 800.78571 | D10: 371728.02 | E10: 111045.82 | F10: 14577.857
A15: .Visits.
A16: PhraseDesc | B16: Total
A17: 1 - Initial Period | B17: 1055.2143
A18: 2 - Pre-Promo | B18: 562.95238
A19: 3 - Promo | B19: 1814.3529
A20: 4 - Post-Promo | B20: 856.57143
A25: .Unique Visits.
A26: PhraseDesc | B26: Total
A27: 1 - Initial Period | B27: 975.92857
A28: 2 - Pre-Promo | B28: 516.80952
A29: 3 - Promo | B29: 1738.8235
A30: 4 - Post-Promo | B30: 800.78571
A37: .Revenue.
A38: PhraseDesc | B38: Total
A39: 1 - Initial Period | B39: 608250.12
A40: 2 - Pre-Promo | B40: 534313.52
A41: 3 - Promo | B41: 456398.85
A42: 4 - Post-Promo | B42: 371728.02
A49: .Profit.
A50: PhraseDesc | B50: Total
A51: 1 - Initial Period | B51: 200233.41
A52: 2 - Pre-Promo | B52: 159932.03
A53: 3 - Promo | B53: 131929.9
A54: 4 - Post-Promo | B54: 111045.82
A66: .Volume.
A67: PhraseDesc | B67: Total
A68: 1 - Initial Period | B68: 18736.714
A69: 2 - Pre-Promo | B69: 18440.857
A70: 3 - Promo | B70: 17112.824
A71: 4 - Post-Promo | B71: 14577.857

Sheet Q4
A9: Analysis
B10: On Unique Visits Week-on-Week (WoW), the central tendency is during the Promo phase, which shows that the marketing campaign initiated pre-promo is effective.
B11: This could mean that leads (part of the 25K marketing budget) have drawn new customers to QA's website.
B12: A rough WoW trend analysis on QA's Sales performance shows a decline going August 2009.
B13: Based only on mean(average) values comparing the 4 periods, the only significant increase is Web Traffc, but even then that didn't translate to an increase in sales.
A15: To wit-- | C15: MEAN
B16: Phrase | C16: .Visits. | D16: .Volume.
B17: 1 - Initial Period | C17: 1055.2143 | D17: 18736.714
B18: 2 - Pre-Promo | C18: 562.95238 | D18: 18440.857
B19: 3 - Promo | C19: 1814.3529 | D19: 17112.824
B20: 4 - Post-Promo | C20: 856.57143 | D20: 14577.857

Sheet Q5
A1: Prepared by (learners):
B2: Gumpal, Peter-Paul
B3: Zuñiga, Ma. Angelica Monina
A14: Analysis
B15: Based on intuition, an increase in sales volume would also translate to revenue growth.
B34: Correlation | D34: =CORREL(SRC!S1:S67,SRC!R1:R67) -> 0.86893384
B36: Correlation Matrix
C37: Volume | D37: Revenue
B38: Volume | C38: 1
B39: Revenue | C39: 0.86893384 | D39: 1
B40: R2 | C40: =C39^2 -> 0.75504602

Sheet Q6
B24: Correlation | D24: =CORREL(SRC!S2:S67,SRC!I2:I67) -> -0.05939183
B26: Correlation Matrix
C27: Visits | D27: Revenue
B28: Visits | C28: 1
B29: Revenue | C29: -0.05939183 | D29: 1

Sheet Q7
A1: Prepared by (learners):
B2: Gumpal, Peter-Paul
B3: Zuñiga, Ma. Angelica Monina
A5: Analysis
B6: Based on our scatter plot (in Q6), which clustered on the left, an increase in Visits didn't translate to increase in sales.
B7: These "new" buyers that have been redirected to QA's could probably have not made or finished a purchase since the website is not designed to be an e-commerce site.
B8: This can be easily verified by the metric "Revenue per Visit" (WoW Revenue / WoW Visits) which shows the gross sales for each website visitor.
B9: By tabulating the average Revenue per Visit per Week for each of the periods, the Promo phase shows the least revenue made per customer transaction in QAs website.
A11: Row Labels | B11: Average of Revenue Per Visit
A12: 1 - Initial Period | B12: 627.76404
A13: 2 - Pre-Promo | B13: 962.16381
A14: 3 - Promo | B14: 288.11628
A15: 4 - Post-Promo | B15: 434.59484
P16: Average of Revenue Per Visit | Q16: Column Labels
P17: Row Labels | Q17: 1 - Initial Period | R17: 2 - Pre-Promo | S17: 3 - Promo | T17: 4 - Post-Promo | V17: Row Labels | W17: Sum of Revenue | X17: Sum of Bounce Rate | Z17: Row Labels | AA17: Sum of Revenue | AB17: Sum of Bounce Rate
P18: 1 | Q18: 294.56373 | V18: 1 | W18: 480728.01 | X18: 0.7267 | Z18: 1 | AA18: 480728.01 | AB18: 0.7267
P19: 2 | Q19: 405.79461 | V19: 2 | W19: 641155.48 | X19: 0.7551 | Z19: 2 | AA19: 641155.48 | AB19: 0.7551
P20: 3 | Q20: 617.67984 | V20: 3 | W20: 890076.65 | X20: 0.7398 | Z20: 3 | AA20: 890076.65 | AB20: 0.7398
P21: 4 | Q21: 380.62946 | V21: 4 | W21: 552673.98 | X21: 0.7362 | Z21: 4 | AA21: 552673.98 | AB21: 0.7362
P22: 5 | Q22: 560.69976 | V22: 5 | W22: 750776.98 | X22: 0.764 | Z22: 5 | AA22: 750776.98 | AB22: 0.764
P23: 6 | Q23: 620.01647 | V23: 6 | W23: 553054.69 | X23: 0.7365 | Z23: 6 | AA23: 553054.69 | AB23: 0.7365
P24: 7 | Q24: 344.5014 | V24: 7 | W24: 274567.61 | X24: 0.6148 | Z24: 7 | AA24: 274567.61 | AB24: 0.6148
P25: 8 | Q25: 832.37182 | V25: 8 | W25: 619284.64 | X25: 0.5927 | Z25: 8 | AA25: 619284.64 | AB25: 0.5927
P26: 9 | Q26: 646.05803 | V26: 9 | W26: 674484.59 | X26: 0.6034 | Z26: 9 | AA26: 674484.59 | AB26: 0.6034
P27: 10 | Q27: 841.67674 | V27: 10 | W27: 762559.12 | X27: 0.6336 | Z27: 10 | AA27: 762559.12 | AB27: 0.6336
P28: 11 | Q28: 564.29231 | V28: 11 | W28: 479084.17 | X28: 0.6443 | Z28: 11 | AA28: 479084.17 | AB28: 0.6443
P29: 12 | Q29: 716.78523 | V29: 12 | W29: 528270.72 | X29: 0.6282 | Z29: 12 | AA29: 528270.72 | AB29: 0.6282
... P31: 14 | Q31: 1227.0114 | V31: 14 | W31: 768109.11 | X31: 0.6198 | Z31: 14 | AA31: 768109.11 | AB31: 0.6198
P32: 15 | R32: 699.86154 | V32: 15 | W32: 403820.11 | X32: 0.6205 | Z32: 15 | AA32: 403820.11 | AB32: 0.6205
A33: Analysis | P33: 16 | R33: 691.71714 | V33: 16 | W33: 388745.03 | X33: 0.589 | Z33: 16 | AA33: 388745.03 | AB33: 0.589
B34: Another variable pair that could be use to analyze the effectiveness of the website is the Bounce Rate and Revenue. This can definitely tell wether a customer visit translated to a sale. | P34: 17 | R34: 1105.4481 | V34: 17 | W34: 622367.3 | X34: 0.5861 | Z34: 17 | AA34: 622367.3 | AB34: 0.5861
B35: As shown in below grown, as the Bounce Rate (percentage of visitors who leave your website after viewing only one page) goes north, sales figure goes south. | P35: 18 | R35: 699.40461 | V35: 18 | W35: 456011.81 | X35: 0.5613 | Z35: 18 | AA35: 456011.81 | AB35: 0.5613
P36: 19 | R36: 1556.8186 | V36: 19 | W36: 951216.16 | X36: 0.5352 | Z36: 19 | AA36: 951216.16 | AB36: 0.5352
P37: 20 | R37: 952.83721 | V37: 20 | W37: 534541.68 | X37: 0.5365 | Z37: 20 | AA37: 534541.68 | AB37: 0.5365
P38: 21 | R38: 963.53386 | V38: 21 | W38: 537651.89 | X38: 0.6129 | Z38: 21 | AA38: 537651.89 | AB38: 0.6129
P39: 22 | R39: 1094.2282 | V39: 22 | W39: 623710.09 | X39: 0.5737 | Z39: 22 | AA39: 623710.09 | AB39: 0.5737
P40: 23 | R40: 1388.0925 | V40: 23 | W40: 764838.99 | X40: 0.5662 | Z40: 23 | AA40: 764838.99 | AB40: 0.5662
P41: 24 | R41: 587.79722 | V41: 24 | W41: 315647.11 | X41: 0.5698 | Z41: 24 | AA41: 315647.11 | AB41: 0.5698
P42: 25 | R42: 1125.2019 | V42: 25 | W42: 610984.66 | X42: 0.5838 | Z42: 25 | AA42: 610984.66 | AB42: 0.5838
P43: 26 | R43: 1009.9009 | V43: 26 | W43: 563524.69 | X43: 0.5771 | Z43: 26 | AA43: 563524.69 | AB43: 0.5771
...

Sheet Q8
A5: 8.a | B5: Descriptive Statistics
B7: Lbs. Sold
B9: Mean | C9: 18681.555
B10: Standard Error | C10: 401.68846
B11: Median | C11: 17673
B12: Mode | C12: 28865
B13: Standard Deviation | C13: 6840.5079
B14: Sample Variance | C14: 46792549
B15: Kurtosis | C15: 0.56366144
B16: Skewness | C16: 0.63230748
B17: Range | C17: 40914
B18: Minimum | C18: 3826
B19: Maximum | C19: 44740
B20: Sum | C20: 5417651
... B22: Confidence Level(95%) | C22: 790.60578
A24: 8.b | B24: Histogram
A41: 8.c | B41: The histogram appears to be bell-shaped, however it ishows a positively skewed data (volume sold more than 30K is at the right tail of the graph) , thus not normally distributed.
A43: 8.d
B44: Interval | C44: Theoretical % of data | D44: Theoretical No. Observation | E44: Actual No. Observation | F44: Actual % of Data
B45: mean +-1 std. dev | C45: 0.68 | D45: =D67 -> 197.2 | E45: =52+72+50 -> 174 | F45: =E45/290 -> 0.6
B46: mean +-2 std. dev | C46: 0.95 | D46: =E67 -> 275.5 | E46: =E45+23+38 -> 235 | F46: =E46/290 -> 0.81034483
B47: mean +-3 std. dev | C47: 0.997 | D47: =F67 -> 289.13 | E47: =E46+7+29 -> 271 | F47: =E47/290 -> 0.93448276
B53: Interval | C53: Actual Observed | D53: stdev | E53: (+-2 stdev) | F53: (+-3 stdev)
B54: 3826 to 7426 | C54: 7 | D54: =C54*$C$45 -> 4.76 | E54: =C54*$C$46 -> 6.65 | F54: =C54*$C$47 -> 6.979 | I54: =61/290 -> 0.21034483
B55: 7426 to 11026 | C55: 23 | D55: =C55*$C$45 -> 15.64 | E55: =C55*$C$46 -> 21.85 | F55: =C55*$C$47 -> 22.931
B56: 11026 to 14626 | C56: 52 | D56: =C56*$C$45 -> 35.36 | E56: =C56*$C$46 -> 49.4 | F56: =C56*$C$47 -> 51.844 | I56: =36/290 -> 0.12413793
B57: 14626 to 18226 | C57: 72 | D57: =C57*$C$45 -> 48.96 | E57: =C57*$C$46 -> 68.4 | F57: =C57*$C$47 -> 71.784
B58: 18226 to 21826 | C58: 50 | D58: =C58*$C$45 -> 34 | E58: =C58*$C$46 -> 47.5 | F58: =C58*$C$47 -> 49.85
B59: 21826 to 25426 | C59: 38 | D59: =C59*$C$45 -> 25.84 | E59: =C59*$C$46 -> 36.1 | F59: =C59*$C$47 -> 37.886
B60: 25426 to 29026 | C60: 29 | D60: =C60*$C$45 -> 19.72 | E60: =C60*$C$46 -> 27.55 | F60: =C60*$C$47 -> 28.913
B61: 29026 to 32626 | C61: 8 | D61: =C61*$C$45 -> 5.44 | E61: =C61*$C$46 -> 7.6 | F61: =C61*$C$47 -> 7.976
B62: 32626 to 36226 | C62: 7 | D62: =C62*$C$45 -> 4.76 | E62: =C62*$C$46 -> 6.65 | F62: =C62*$C$47 -> 6.979
B63: 36226 o 39826 | C63: 2 | D63: =C63*$C$45 -> 1.36 | E63: =C63*$C$46 -> 1.9 | F63: =C63*$C$47 -> 1.994
B64: 39826 to 43426 | C64: 1 | D64: =C64*$C$45 -> 0.68 | E64: =C64*$C$46 -> 0.95 | F64: =C64*$C$47 -> 0.997
B65: 43426t to 47026 | C65: 1 | D65: =C65*$C$45 -> 0.68 | E65: =C65*$C$46 -> 0.95 | F65: =C65*$C$47 -> 0.997
D67: =SUM(D54:D65) -> 197.2 | E67: =SUM(E54:E65) -> 275.5 | F67: =SUM(F54:F65) -> 289.13
A69: 8.e
B70: Interval | C70: Theoretical % of data | D70: Theoretical No. Observation | E70: Actual No. Observation
B71: mean +1 std. dev | C71: =C45/2 -> 0.34 | D71: =D67*C71 -> 67.048 | E71: 35
B72: mean -1 std. dev | C72: =C45/2 -> 0.34 | D72: =D67*C72 -> 67.048 | E72: 0
...

Sheet Q9
A1: Prepared by (learners):
B2: Gumpal, Peter-Paul
B3: Zuñiga, Ma. Angelica Monina
B10: {='Daily Visits'!H1:I16} -> Visits | C10: 0
B11: 0 | C11: 0
B12: Mean | C12: 150.28355
B13: Standard Error | C13: 4.5672581
B14: Median | C14: 122
B15: Mode | C15: 91
B16: Standard Deviation | C16: 98.169492
B17: Sample Variance | C17: 9637.2491
B18: Kurtosis | C18: 5.8619896
B19: Skewness | C19: 2.1669722
B20: Range | C20: 627
B21: Minimum | C21: 37
B22: Maximum | C22: 664
B23: Sum | C23: 69431
... B25: Confidence Level(95%) | C25: 8.9752246
B27: Interval | C27: Theoretical % of data | D27: Theoretical No. Observation | E27: Actual No. Observation | F27: Actual % of data
B28: mean +-1 std. dev | C28: 0.68 | D28: =C28*462 -> 314.16 | E28: =151+92+54 -> 297 | F28: =E28/$C$24 -> 0.64285714
B29: mean +-2 std. dev | C29: 0.95 | D29: =C29*462 -> 438.9 | E29: =E28+85+36 -> 418 | F29: =E29/$C$24 -> 0.9047619
B30: mean +-3 std. dev | C30: 0.997 | D30: =C30*462 -> 460.614 | E30: =E29+11 -> 429 | F30: =E30/$C$24 -> 0.92857143
B35: Interval | C35: Actual Observed | D35: stdev | E35: (+-2 stdev) | F35: (+-3 stdev)
B36: 37 to 81 | C36: 85 | D36: =C36*$C$28 -> 57.8 | E36: =C36*$C$29 -> 80.75 | F36: =C36*$C$30 -> 84.745
B37: 81 to 125 | C37: 151 | D37: =C37*$C$28 -> 102.68 | E37: =C37*$C$29 -> 143.45 | F37: =C37*$C$30 -> 150.547
B38: 125 to 169 | C38: 92 | D38: =C38*$C$28 -> 62.56 | E38: =C38*$C$29 -> 87.4 | F38: =C38*$C$30 -> 91.724
B39: 169 to 213 | C39: 54 | D39: =C39*$C$28 -> 36.72 | E39: =C39*$C$29 -> 51.3 | F39: =C39*$C$30 -> 53.838
B40: 213 to 257 | C40: 36 | D40: =C40*$C$28 -> 24.48 | E40: =C40*$C$29 -> 34.2 | F40: =C40*$C$30 -> 35.892
B41: 257 to 301 | C41: 11 | D41: =C41*$C$28 -> 7.48 | E41: =C41*$C$29 -> 10.45 | F41: =C41*$C$30 -> 10.967
B42: 301 to 345 | C42: 10 | D42: =C42*$C$28 -> 6.8 | E42: =C42*$C$29 -> 9.5 | F42: =C42*$C$30 -> 9.97
B43: 345 to 389 | C43: 4 | D43: =C43*$C$28 -> 2.72 | E43: =C43*$C$29 -> 3.8 | F43: =C43*$C$30 -> 3.988
B44: 389 to 433 | C44: 4 | D44: =C44*$C$28 -> 2.72 | E44: =C44*$C$29 -> 3.8 | F44: =C44*$C$30 -> 3.988
B45: 433 to 477 | C45: 4 | D45: =C45*$C$28 -> 2.72 | E45: =C45*$C$29 -> 3.8 | F45: =C45*$C$30 -> 3.988
B46: 477 to 521 | C46: 5 | D46: =C46*$C$28 -> 3.4 | E46: =C46*$C$29 -> 4.75 | F46: =C46*$C$30 -> 4.985
B47: 521 to 565 | C47: 4 | D47: =C47*$C$28 -> 2.72 | E47: =C47*$C$29 -> 3.8 | F47: =C47*$C$30 -> 3.988
... B50: 653 to 697 | C50: 1 | D50: =C50*$C$28 -> 0.68 | E50: =C50*$C$29 -> 0.95 | F50: =C50*$C$30 -> 0.997
D52: =SUM(D36:D50) -> 314.16 | E52: =SUM(E36:E50) -> 438.9 | F52: =SUM(F36:F50) -> 460.614
B54: Daily Visits | H54: Lbs. Sold
B55: Interval | C55: Theoretical % of data | D55: Theoretical No. Observation | E55: Actual No. Observation | H55: Interval | I55: Theoretical % of data | J55: Theoretical No. Observation | K55: Actual No. Observation
B56: mean +1 std. dev | C56: =C28/2 -> 0.34 | D56: =C56*462 -> 157.08 | E56: 0 | H56: mean +1 std. dev | I56: 0.34 | J56: 67.048 | K56: 35
...

Sheet Q10
A1: Prepared by (learners):
B2: Gumpal, Peter-Paul
B3: Zuñiga, Ma. Angelica Monina
A10: Analysis
A11: 1 | B11: The majority of traffic to QA's website (86%) comes from referring sites and search engines, suggesting that the brochure had a limited impact on site visits.
B12: It can be inferred that only 14% of visits may be attributed to direct communication with leads.
A13: 2 | B13: Google AdWords, a separate service from the brochure, contributes significantly to website traffic (approximately 80%).
A14: 3 | B14: With Google being the top search engine source of visits, utilizing Google's ad service remains a viable option for QA.
A15: 4 | B15: The Americas represent QA's largest customer base (71%), while Europe and Asia are potential targets for future marketing campaigns.
A16: 5 | B16: Given that most visitors find QA through Google and primarily use Internet Explorer on Windows PCs (76% of total visits), these insights should inform the design of QA's future website.
A19: Chart 1
A34: Chart 2
A52: Chart 3
A71: Chart 4
A92: Chart 5

Sheet DS_LbsSold
A1: Phase | B1: PhraseDesc | C1: PhaseCode | D1: WeekCode | E1: MonthCode | F1: MonthYear | G1: Year | H1: Week | I1: Lbs. Sold | J1: z-score | K1: Count | N1: Count3 | X1: MonthCode | Y1: Lbs. Sold | AA1: Descriptive Statistics
A2: Pre-WebAnalytics | B2: =_xlfn.CONCAT(C2, " - ", A2) -> 0 - Pre-WebAnalytics | C2: 0 | D2: 1 | E2: =_xlfn.CONCAT(G2, " - ", F2) -> 2005 - 01 | F2: =TEXT(H2,"mm") -> 01 | G2: =TEXT(H2,"YYYY") -> 2005 | H2: 38354 | I2: 23662 | J2: =(I2-$AB$4) / $AB$8 -> 0.72808114 | K2: =IF(J2<=1, "<=1", IF(J2<=2, "<=2", IF(J2<=3, "<=3", "<=3"))) -> <=1 | N2: =IF(J2>=3, 3, IF(J2>=2, 2, IF(J2>=1, 1, IF(J2>=-2, -2, IF(J2>=-3, -3, "Error"))))) -> -2 | X2: 2005 - 01 | Y2: 23662 | AA2: Lbs. Sold
A3: Pre-WebAnalytics | B3: =_xlfn.CONCAT(C3, " - ", A3) -> 0 - Pre-WebAnalytics | C3: 0 | D3: 2 | E3: =_xlfn.CONCAT(G3, " - ", F3) -> 2005 - 01 | F3: =TEXT(H3,"mm") -> 01 | G3: =TEXT(H3,"YYYY") -> 2005 | H3: 38361 | I3: 12699 | J3: =(I3-$AB$4) / $AB$8 -> -0.87457762 | K3: =IF(J3<=1, "<=1", IF(J3<=2, "<=2", IF(J3<=3, "<=3", "<=3"))) -> <=1 | N3: =IF(J3>=3, 3, IF(J3>=2, 2, IF(J3>=1, 1, IF(J3>=-2, -2, IF(J3>=-3, -3, "Error"))))) -> -2 | O3: Sum of Lbs. Sold | P3: Column Labels | X3: 2005 - 01 | Y3: 12699
A4: Pre-WebAnalytics | B4: =_xlfn.CONCAT(C4, " - ", A4) -> 0 - Pre-WebAnalytics | C4: 0 | D4: 3 | E4: =_xlfn.CONCAT(G4, " - ", F4) -> 2005 - 01 | F4: =TEXT(H4,"mm") -> 01 | G4: =TEXT(H4,"YYYY") -> 2005 | H4: 38368 | I4: 23095 | J4: =(I4-$AB$4) / $AB$8 -> 0.64519256 | K4: =IF(J4<=1, "<=1", IF(J4<=2, "<=2", IF(J4<=3, "<=3", "<=3"))) -> <=1 | N4: =IF(J4>=3, 3, IF(J4>=2, 2, IF(J4>=1, 1, IF(J4>=-2, -2, IF(J4>=-3, -3, "Error"))))) -> -2 | O4: Row Labels | P4: 0 | Q4: 1 | R4: 2 | S4: 3 | T4: 4 | U4: 5 | X4: 2005 - 01 | Y4: 23095 | AA4: Mean | AB4: 18681.555
A5: Pre-WebAnalytics | B5: =_xlfn.CONCAT(C5, " - ", A5) -> 0 - Pre-WebAnalytics | C5: 0 | D5: 4 | E5: =_xlfn.CONCAT(G5, " - ", F5) -> 2005 - 01 | F5: =TEXT(H5,"mm") -> 01 | G5: =TEXT(H5,"YYYY") -> 2005 | H5: 38375 | I5: 27944 | J5: =(I5-$AB$4) / $AB$8 -> 1.354058 | K5: =IF(J5<=1, "<=1", IF(J5<=2, "<=2", IF(J5<=3, "<=3", "<=3"))) -> <=2 | N5: =IF(J5>=3, 3, IF(J5>=2, 2, IF(J5>=1, 1, IF(J5>=-2, -2, IF(J5>=-3, -3, "Error"))))) -> 1 | O5: 0 - Pre-WebAnalytics | X5: 2005 - 01 | Y5: 27944 | AA5: Standard Error | AB5: 401.68846
A6: Pre-WebAnalytics | B6: =_xlfn.CONCAT(C6, " - ", A6) -> 0 - Pre-WebAnalytics | C6: 0 | D6: 5 | E6: =_xlfn.CONCAT(G6, " - ", F6) -> 2005 - 01 | F6: =TEXT(H6,"mm") -> 01 | G6: =TEXT(H6,"YYYY") -> 2005 | H6: 38382 | I6: 20516 | J6: =(I6-$AB$4) / $AB$8 -> 0.26817377 | K6: =IF(J6<=1, "<=1", IF(J6<=2, "<=2", IF(J6<=3, "<=3", "<=3"))) -> <=1 | N6: =IF(J6>=3, 3, IF(J6>=2, 2, IF(J6>=1, 1, IF(J6>=-2, -2, IF(J6>=-3, -3, "Error"))))) -> -2 | O6: 1 | P6: 23662 | X6: 2005 - 01 | Y6: 20516 | AA6: Median | AB6: 17673
A7: Pre-WebAnalytics | B7: =_xlfn.CONCAT(C7, " - ", A7) -> 0 - Pre-WebAnalytics | C7: 0 | D7: 6 | E7: =_xlfn.CONCAT(G7, " - ", F7) -> 2005 - 02 | F7: =TEXT(H7,"mm") -> 02 | G7: =TEXT(H7,"YYYY") -> 2005 | H7: 38389 | I7: 25546 | J7: =(I7-$AB$4) / $AB$8 -> 1.0034993 | K7: =IF(J7<=1, "<=1", IF(J7<=2, "<=2", IF(J7<=3, "<=3", "<=3"))) -> <=2 | N7: =IF(J7>=3, 3, IF(J7>=2, 2, IF(J7>=1, 1, IF(J7>=-2, -2, IF(J7>=-3, -3, "Error"))))) -> 1 | O7: 2 | P7: 12699 | X7: 2005 - 02 | Y7: 25546 | AA7: Mode | AB7: 28865
A8: Pre-WebAnalytics | B8: =_xlfn.CONCAT(C8, " - ", A8) -> 0 - Pre-WebAnalytics | C8: 0 | D8: 7 | E8: =_xlfn.CONCAT(G8, " - ", F8) -> 2005 - 02 | F8: =TEXT(H8,"mm") -> 02 | G8: =TEXT(H8,"YYYY") -> 2005 | H8: 38396 | I8: 20023 | J8: =(I8-$AB$4) / $AB$8 -> 0.1961031 | K8: =IF(J8<=1, "<=1", IF(J8<=2, "<=2", IF(J8<=3, "<=3", "<=3"))) -> <=1 | N8: =IF(J8>=3, 3, IF(J8>=2, 2, IF(J8>=1, 1, IF(J8>=-2, -2, IF(J8>=-3, -3, "Error"))))) -> -2 | O8: 3 | P8: 23095 | X8: 2005 - 02 | Y8: 20023 | AA8: Standard Deviation | AB8: 6840.5079
A9: Pre-WebAnalytics | B9: =_xlfn.CONCAT(C9, " - ", A9) -> 0 - Pre-WebAnalytics | C9: 0 | D9: 8 | E9: =_xlfn.CONCAT(G9, " - ", F9) -> 2005 - 02 | F9: =TEXT(H9,"mm") -> 02 | G9: =TEXT(H9,"YYYY") -> 2005 | H9: 38403 | I9: 35247 | J9: =(I9-$AB$4) / $AB$8 -> 2.4216688 | K9: =IF(J9<=1, "<=1", IF(J9<=2, "<=2", IF(J9<=3, "<=3", "<=3"))) -> <=3 | N9: =IF(J9>=3, 3, IF(J9>=2, 2, IF(J9>=1, 1, IF(J9>=-2, -2, IF(J9>=-3, -3, "Error"))))) -> 2 | O9: 4 | P9: 27944 | X9: 2005 - 02 | Y9: 35247 | AA9: Sample Variance | AB9: 46792549
A10: Pre-WebAnalytics | B10: =_xlfn.CONCAT(C10, " - ", A10) -> 0 - Pre-WebAnalytics | C10: 0 | D10: 9 | E10: =_xlfn.CONCAT(G10, " - ", F10) -> 2005 - 02 | F10: =TEXT(H10,"mm") -> 02 | G10: =TEXT(H10,"YYYY") -> 2005 | H10: 38410 | I10: 23615 | J10: =(I10-$AB$4) / $AB$8 -> 0.72121031 | K10: =IF(J10<=1, "<=1", IF(J10<=2, "<=2", IF(J10<=3, "<=3", "<=3"))) -> <=1 | N10: =IF(J10>=3, 3, IF(J10>=2, 2, IF(J10>=1, 1, IF(J10>=-2, -2, IF(J10>=-3, -3, "Error"))))) -> -2 | O10: 5 | P10: 20516 | X10: 2005 - 02 | Y10: 23615 | AA10: Kurtosis | AB10: 0.56366144
A11: Pre-WebAnalytics | B11: =_xlfn.CONCAT(C11, " - ", A11) -> 0 - Pre-WebAnalytics | C11: 0 | D11: 10 | E11: =_xlfn.CONCAT(G11, " - ", F11) -> 2005 - 03 | F11: =TEXT(H11,"mm") -> 03 | G11: =TEXT(H11,"YYYY") -> 2005 | H11: 38417 | I11: 16655 | J11: =(I11-$AB$4) / $AB$8 -> -0.296258 | K11: =IF(J11<=1, "<=1", IF(J11<=2, "<=2", IF(J11<=3, "<=3", "<=3"))) -> <=1 | N11: =IF(J11>=3, 3, IF(J11>=2, 2, IF(J11>=1, 1, IF(J11>=-2, -2, IF(J11>=-3, -3, "Error"))))) -> -2 | O11: 6 | P11: 25546 | X11: 2005 - 03 | Y11: 16655 | AA11: Skewness | AB11: 0.63230748
A12: Pre-WebAnalytics | B12: =_xlfn.CONCAT(C12, " - ", A12) -> 0 - Pre-WebAnalytics | C12: 0 | D12: 11 | E12: =_xlfn.CONCAT(G12, " - ", F12) -> 2005 - 03 | F12: =TEXT(H12,"mm") -> 03 | G12: =TEXT(H12,"YYYY") -> 2005 | H12: 38424 | I12: 14748 | J12: =(I12-$AB$4) / $AB$8 -> -0.57503846 | K12: =IF(J12<=1, "<=1", IF(J12<=2, "<=2", IF(J12<=3, "<=3", "<=3"))) -> <=1 | N12: =IF(J12>=3, 3, IF(J12>=2, 2, IF(J12>=1, 1, IF(J12>=-2, -2, IF(J12>=-3, -3, "Error"))))) -> -2 | O12: 7 | P12: 20023 | X12: 2005 - 03 | Y12: 14748 | AA12: Range | AB12: 40914
A13: Pre-WebAnalytics | B13: =_xlfn.CONCAT(C13, " - ", A13) -> 0 - Pre-WebAnalytics | C13: 0 | D13: 12 | E13: =_xlfn.CONCAT(G13, " - ", F13) -> 2005 - 03 | F13: =TEXT(H13,"mm") -> 03 | G13: =TEXT(H13,"YYYY") -> 2005 | H13: 38431 | I13: 18159 | J13: =(I13-$AB$4) / $AB$8 -> -0.076391282 | K13: =IF(J13<=1, "<=1", IF(J13<=2, "<=2", IF(J13<=3, "<=3", "<=3"))) -> <=1 | N13: =IF(J13>=3, 3, IF(J13>=2, 2, IF(J13>=1, 1, IF(J13>=-2, -2, IF(J13>=-3, -3, "Error"))))) -> -2 | O13: 8 | P13: 35247 | X13: 2005 - 03 | Y13: 18159 | AA13: Minimum | AB13: 3826
A14: Pre-WebAnalytics | B14: =_xlfn.CONCAT(C14, " - ", A14) -> 0 - Pre-WebAnalytics | C14: 0 | D14: 13 | E14: =_xlfn.CONCAT(G14, " - ", F14) -> 2005 - 03 | F14: =TEXT(H14,"mm") -> 03 | G14: =TEXT(H14,"YYYY") -> 2005 | H14: 38438 | I14: 22149 | J14: =(I14-$AB$4) / $AB$8 -> 0.50689874 | K14: =IF(J14<=1, "<=1", IF(J14<=2, "<=2", IF(J14<=3, "<=3", "<=3"))) -> <=1 | N14: =IF(J14>=3, 3, IF(J14>=2, 2, IF(J14>=1, 1, IF(J14>=-2, -2, IF(J14>=-3, -3, "Error"))))) -> -2 | O14: 9 | P14: 23615 | X14: 2005 - 03 | Y14: 22149 | AA14: Maximum | AB14: 44740
A15: Pre-WebAnalytics | B15: =_xlfn.CONCAT(C15, " - ", A15) -> 0 - Pre-WebAnalytics | C15: 0 | D15: 14 | E15: =_xlfn.CONCAT(G15, " - ", F15) -> 2005 - 04 | F15: =TEXT(H15,"mm") -> 04 | G15: =TEXT(H15,"YYYY") -> 2005 | H15: 38445 | I15: 14492 | J15: =(I15-$AB$4) / $AB$8 -> -0.61246258 | K15: =IF(J15<=1, "<=1", IF(J15<=2, "<=2", IF(J15<=3, "<=3", "<=3"))) -> <=1 | N15: =IF(J15>=3, 3, IF(J15>=2, 2, IF(J15>=1, 1, IF(J15>=-2, -2, IF(J15>=-3, -3, "Error"))))) -> -2 | O15: 10 | P15: 16655 | X15: 2005 - 04 | Y15: 14492 | AA15: Sum | AB15: 5417651
A16: Pre-WebAnalytics | B16: =_xlfn.CONCAT(C16, " - ", A16) -> 0 - Pre-WebAnalytics | C16: 0 | D16: 15 | E16: =_xlfn.CONCAT(G16, " - ", F16) -> 2005 - 04 | F16: =TEXT(H16,"mm") -> 04 | G16: =TEXT(H16,"YYYY") -> 2005 | H16: 38452 | I16: 19012 | J16: =(I16-$AB$4) / $AB$8 -> 0.04830706 | K16: =IF(J16<=1, "<=1", IF(J16<=2, "<=2", IF(J16<=3, "<=3", "<=3"))) -> <=1 | N16: =IF(J16>=3, 3, IF(J16>=2, 2, IF(J16>=1, 1, IF(J16>=-2, -2, IF(J16>=-3, -3, "Error"))))) -> -2 | O16: 11 | P16: 14748 | X16: 2005 - 04 | Y16: 19012 | AA16: Count | AB16: 290
A17: Pre-WebAnalytics | B17: =_xlfn.CONCAT(C17, " - ", A17) -> 0 - Pre-WebAnalytics | C17: 0 | D17: 16 | E17: =_xlfn.CONCAT(G17, " - ", F17) -> 2005 - 04 | F17: =TEXT(H17,"mm") -> 04 | G17: =TEXT(H17,"YYYY") -> 2005 | H17: 38459 | I17: 14678 | J17: =(I17-$AB$4) / $AB$8 -> -0.58527162 | K17: =IF(J17<=1, "<=1", IF(J17<=2, "<=2", IF(J17<=3, "<=3", "<=3"))) -> <=1 | N17: =IF(J17>=3, 3, IF(J17>=2, 2, IF(J17>=1, 1, IF(J17>=-2, -2, IF(J17>=-3, -3, "Error"))))) -> -2 | O17: 12 | P17: 18159 | X17: 2005 - 04 | Y17: 14678 | AA17: Confidence Level(95%) | AB17: 790.60578
A18: Pre-WebAnalytics | B18: =_xlfn.CONCAT(C18, " - ", A18) -> 0 - Pre-WebAnalytics | C18: 0 | D18: 17 | E18: =_xlfn.CONCAT(G18, " - ", F18) -> 2005 - 04 | F18: =TEXT(H18,"mm") -> 04 | G18: =TEXT(H18,"YYYY") -> 2005 | H18: 38466 | I18: 30844 | J18: =(I18-$AB$4) / $AB$8 -> 1.7780032 | K18: =IF(J18<=1, "<=1", IF(J18<=2, "<=2", IF(J18<=3, "<=3", "<=3"))) -> <=2 | N18: =IF(J18>=3, 3, IF(J18>=2, 2, IF(J18>=1, 1, IF(J18>=-2, -2, IF(J18>=-3, -3, "Error"))))) -> 1 | O18: 13 | P18: 22149 | X18: 2005 - 04 | Y18: 30844
A19: Pre-WebAnalytics | B19: =_xlfn.CONCAT(C19, " - ", A19) -> 0 - Pre-WebAnalytics | C19: 0 | D19: 18 | E19: =_xlfn.CONCAT(G19, " - ", F19) -> 2005 - 05 | F19: =TEXT(H19,"mm") -> 05 | G19: =TEXT(H19,"YYYY") -> 2005 | H19: 38473 | I19: 17701 | J19: =(I19-$AB$4) / $AB$8 -> -0.14334537 | K19: =IF(J19<=1, "<=1", IF(J19<=2, "<=2", IF(J19<=3, "<=3", "<=3"))) -> <=1 | N19: =IF(J19>=3, 3, IF(J19>=2, 2, IF(J19>=1, 1, IF(J19>=-2, -2, IF(J19>=-3, -3, "Error"))))) -> -2 | O19: 14 | P19: 14492 | X19: 2005 - 05 | Y19: 17701
A20: Pre-WebAnalytics | B20: =_xlfn.CONCAT(C20, " - ", A20) -> 0 - Pre-WebAnalytics | C20: 0 | D20: 19 | E20: =_xlfn.CONCAT(G20, " - ", F20) -> 2005 - 05 | F20: =TEXT(H20,"mm") -> 05 | G20: =TEXT(H20,"YYYY") -> 2005 | H20: 38480 | I20: 15220 | J20: =(I20-$AB$4) / $AB$8 -> -0.50603774 | K20: =IF(J20<=1, "<=1", IF(J20<=2, "<=2", IF(J20<=3, "<=3", "<=3"))) -> <=1 | N20: =IF(J20>=3, 3, IF(J20>=2, 2, IF(J20>=1, 1, IF(J20>=-2, -2, IF(J20>=-3, -3, "Error"))))) -> -2 | O20: 15 | P20: 19012 | X20: 2005 - 05 | Y20: 15220
A21: Pre-WebAnalytics | B21: =_xlfn.CONCAT(C21, " - ", A21) -> 0 - Pre-WebAnalytics | C21: 0 | D21: 20 | E21: =_xlfn.CONCAT(G21, " - ", F21) -> 2005 - 05 | F21: =TEXT(H21,"mm") -> 05 | G21: =TEXT(H21,"YYYY") -> 2005 | H21: 38487 | I21: 15504 | J21: =(I21-$AB$4) / $AB$8 -> -0.46452035 | K21: =IF(J21<=1, "<=1", IF(J21<=2, "<=2", IF(J21<=3, "<=3", "<=3"))) -> <=1 | N21: =IF(J21>=3, 3, IF(J21>=2, 2, IF(J21>=1, 1, IF(J21>=-2, -2, IF(J21>=-3, -3, "Error"))))) -> -2 | O21: 16 | P21: 14678 | X21: 2005 - 05 | Y21: 15504
A22: Pre-WebAnalytics | B22: =_xlfn.CONCAT(C22, " - ", A22) -> 0 - Pre-WebAnalytics | C22: 0 | D22: 21 | E22: =_xlfn.CONCAT(G22, " - ", F22) -> 2005 - 05 | F22: =TEXT(H22,"mm") -> 05 | G22: =TEXT(H22,"YYYY") -> 2005 | H22: 38494 | I22: 23957 | J22: =(I22-$AB$4) / $AB$8 -> 0.77120659 | K22: =IF(J22<=1, "<=1", IF(J22<=2, "<=2", IF(J22<=3, "<=3", "<=3"))) -> <=1 | N22: =IF(J22>=3, 3, IF(J22>=2, 2, IF(J22>=1, 1, IF(J22>=-2, -2, IF(J22>=-3, -3, "Error"))))) -> -2 | O22: 17 | P22: 30844 | X22: 2005 - 05 | Y22: 23957
A23: Pre-WebAnalytics | B23: =_xlfn.CONCAT(C23, " - ", A23) -> 0 - Pre-WebAnalytics | C23: 0 | D23: 22 | E23: =_xlfn.CONCAT(G23, " - ", F23) -> 2005 - 05 | F23: =TEXT(H23,"mm") -> 05 | G23: =TEXT(H23,"YYYY") -> 2005 | H23: 38501 | I23: 16153 | J23: =(I23-$AB$4) / $AB$8 -> -0.36964436 | K23: =IF(J23<=1, "<=1", IF(J23<=2, "<=2", IF(J23<=3, "<=3", "<=3"))) -> <=1 | N23: =IF(J23>=3, 3, IF(J23>=2, 2, IF(J23>=1, 1, IF(J23>=-2, -2, IF(J23>=-3, -3, "Error"))))) -> -2 | O23: 18 | P23: 17701 | X23: 2005 - 05 | Y23: 16153
A24: Pre-WebAnalytics | B24: =_xlfn.CONCAT(C24, " - ", A24) -> 0 - Pre-WebAnalytics | C24: 0 | D24: 23 | E24: =_xlfn.CONCAT(G24, " - ", F24) -> 2005 - 06 | F24: =TEXT(H24,"mm") -> 06 | G24: =TEXT(H24,"YYYY") -> 2005 | H24: 38508 | I24: 15901 | J24: =(I24-$AB$4) / $AB$8 -> -0.40648373 | K24: =IF(J24<=1, "<=1", IF(J24<=2, "<=2", IF(J24<=3, "<=3", "<=3"))) -> <=1 | N24: =IF(J24>=3, 3, IF(J24>=2, 2, IF(J24>=1, 1, IF(J24>=-2, -2, IF(J24>=-3, -3, "Error"))))) -> -2 | O24: 19 | P24: 15220 | X24: 2005 - 06 | Y24: 15901
A25: Pre-WebAnalytics | B25: =_xlfn.CONCAT(C25, " - ", A25) -> 0 - Pre-WebAnalytics | C25: 0 | D25: 24 | E25: =_xlfn.CONCAT(G25, " - ", F25) -> 2005 - 06 | F25: =TEXT(H25,"mm") -> 06 | G25: =TEXT(H25,"YYYY") -> 2005 | H25: 38515 | I25: 26637 | J25: =(I25-$AB$4) / $AB$8 -> 1.1629904 | K25: =IF(J25<=1, "<=1", IF(J25<=2, "<=2", IF(J25<=3, "<=3", "<=3"))) -> <=2 | N25: =IF(J25>=3, 3, IF(J25>=2, 2, IF(J25>=1, 1, IF(J25>=-2, -2, IF(J25>=-3, -3, "Error"))))) -> 1 | O25: 20 | P25: 15504 | X25: 2005 - 06 | Y25: 26637
A26: Pre-WebAnalytics | B26: =_xlfn.CONCAT(C26, " - ", A26) -> 0 - Pre-WebAnalytics | C26: 0 | D26: 25 | E26: =_xlfn.CONCAT(G26, " - ", F26) -> 2005 - 06 | F26: =TEXT(H26,"mm") -> 06 | G26: =TEXT(H26,"YYYY") -> 2005 | H26: 38522 | I26: 16538 | J26: =(I26-$AB$4) / $AB$8 -> -0.31336199 | K26: =IF(J26<=1, "<=1", IF(J26<=2, "<=2", IF(J26<=3, "<=3", "<=3"))) -> <=1 | N26: =IF(J26>=3, 3, IF(J26>=2, 2, IF(J26>=1, 1, IF(J26>=-2, -2, IF(J26>=-3, -3, "Error"))))) -> -2 | O26: 21 | P26: 23957 | X26: 2005 - 06 | Y26: 16538
A27: Pre-WebAnalytics | B27: =_xlfn.CONCAT(C27, " - ", A27) -> 0 - Pre-WebAnalytics | C27: 0 | D27: 26 | E27: =_xlfn.CONCAT(G27, " - ", F27) -> 2005 - 06 | F27: =TEXT(H27,"mm") -> 06 | G27: =TEXT(H27,"YYYY") -> 2005 | H27: 38529 | I27: 26581 | J27: =(I27-$AB$4) / $AB$8 -> 1.1548038 | K27: =IF(J27<=1, "<=1", IF(J27<=2, "<=2", IF(J27<=3, "<=3", "<=3"))) -> <=2 | N27: =IF(J27>=3, 3, IF(J27>=2, 2, IF(J27>=1, 1, IF(J27>=-2, -2, IF(J27>=-3, -3, "Error"))))) -> 1 | O27: 22 | P27: 16153 | X27: 2005 - 06 | Y27: 26581
A28: Pre-WebAnalytics | B28: =_xlfn.CONCAT(C28, " - ", A28) -> 0 - Pre-WebAnalytics | C28: 0 | D28: 27 | E28: =_xlfn.CONCAT(G28, " - ", F28) -> 2005 - 07 | F28: =TEXT(H28,"mm") -> 07 | G28: =TEXT(H28,"YYYY") -> 2005 | H28: 38536 | I28: 4536 | J28: =(I28-$AB$4) / $AB$8 -> -2.0679101 | K28: =IF(J28<=1, "<=1", IF(J28<=2, "<=2", IF(J28<=3, "<=3", "<=3"))) -> <=1 | N28: =IF(J28>=3, 3, IF(J28>=2, 2, IF(J28>=1, 1, IF(J28>=-2, -2, IF(J28>=-3, -3, "Error"))))) -> -3 | O28: 23 | P28: 15901 | X28: 2005 - 07 | Y28: 4536
A29: Pre-WebAnalytics | B29: =_xlfn.CONCAT(C29, " - ", A29) -> 0 - Pre-WebAnalytics | C29: 0 | D29: 28 | E29: =_xlfn.CONCAT(G29, " - ", F29) -> 2005 - 07 | F29: =TEXT(H29,"mm") -> 07 | G29: =TEXT(H29,"YYYY") -> 2005 | H29: 38543 | I29: 26737 | J29: =(I29-$AB$4) / $AB$8 -> 1.1776092 | K29: =IF(J29<=1, "<=1", IF(J29<=2, "<=2", IF(J29<=3, "<=3", "<=3"))) -> <=2 | N29: =IF(J29>=3, 3, IF(J29>=2, 2, IF(J29>=1, 1, IF(J29>=-2, -2, IF(J29>=-3, -3, "Error"))))) -> 1 | O29: 24 | P29: 26637 | X29: 2005 - 07 | Y29: 26737
... A117: Pre-WebAnalytics | B117: =_xlfn.CONCAT(C117, " - ", A117) -> 0 - Pre-WebAnalytics | C117: 0 | D117: 116 | E117: =_xlfn.CONCAT(G117, " - ", F117) -> 2007 - 03 | F117: =TEXT(H117,"mm") -> 03 | G117: =TEXT(H117,"YYYY") -> 2007 | H117: 39159 | I117: 12426 | J117: =(I117-$AB$4) / $AB$8 -> -0.91448694 | K117: =IF(J117<=1, "<=1", IF(J117<=2, "<=2", IF(J117<=3, "<=3", "<=3"))) -> <=1 | N117: =IF(J117>=3, 3, IF(J117>=2, 2, IF(J117>=1, 1, IF(J117>=-2, -2, IF(J117>=-3, -3, "Error"))))) -> -2 | O117: 112 | P117: 23178 | X117: 2007 - 03 | Y117: 12426
A118: Pre-WebAnalytics | B118: =_xlfn.CONCAT(C118, " - ", A118) -> 0 - Pre-WebAnalytics | C118: 0 | D118: 117 | E118: =_xlfn.CONCAT(G118, " - ", F118) -> 2007 - 03 | F118: =TEXT(H118,"mm") -> 03 | G118: =TEXT(H118,"YYYY") -> 2007 | H118: 39166 | I118: 32266 | J118: =(I118-$AB$4) / $AB$8 -> 1.9858825 | K118: =IF(J118<=1, "<=1", IF(J118<=2, "<=2", IF(J118<=3, "<=3", "<=3"))) -> <=2 | L118: =COUNTA(K84:K118) -> 35 | M118: =1-(L118/L133) -> #DIV/0! | N118: =IF(J118>=3, 3, IF(J118>=2, 2, IF(J118>=1, 1, IF(J118>=-2, -2, IF(J118>=-3, -3, "Error"))))) -> 1 | O118: 113 | P118: 24919 | X118: 2007 - 03 | Y118: 32266
A119: Pre-WebAnalytics | B119: =_xlfn.CONCAT(C119, " - ", A119) -> 0 - Pre-WebAnalytics | C119: 0 | D119: 118 | E119: =_xlfn.CONCAT(G119, " - ", F119) -> 2007 - 04 | F119: =TEXT(H119,"mm") -> 04 | G119: =TEXT(H119,"YYYY") -> 2007 | H119: 39173 | I119: 21981 | J119: =(I119-$AB$4) / $AB$8 -> 0.48233916 | K119: =IF(J119<=1, "<=1", IF(J119<=2, "<=2", IF(J119<=3, "<=3", "<=3"))) -> <=1 | N119: =IF(J119>=3, 3, IF(J119>=2, 2, IF(J119>=1, 1, IF(J119>=-2, -2, IF(J119>=-3, -3, "Error"))))) -> -2 | O119: 114 | P119: 15258 | X119: 2007 - 04 | Y119: 21981
A120: Pre-WebAnalytics | B120: =_xlfn.CONCAT(C120, " - ", A120) -> 0 - Pre-WebAnalytics | C120: 0 | D120: 119 | E120: =_xlfn.CONCAT(G120, " - ", F120) -> 2007 - 04 | F120: =TEXT(H120,"mm") -> 04 | G120: =TEXT(H120,"YYYY") -> 2007 | H120: 39180 | I120: 12558 | J120: =(I120-$AB$4) / $AB$8 -> -0.89519013 | K120: =IF(J120<=1, "<=1", IF(J120<=2, "<=2", IF(J120<=3, "<=3", "<=3"))) -> <=1 | N120: =IF(J120>=3, 3, IF(J120>=2, 2, IF(J120>=1, 1, IF(J120>=-2, -2, IF(J120>=-3, -3, "Error"))))) -> -2 | O120: 115 | P120: 8492 | X120: 2007 - 04 | Y120: 12558
A121: Pre-WebAnalytics | B121: =_xlfn.CONCAT(C121, " - ", A121) -> 0 - Pre-WebAnalytics | C121: 0 | D121: 120 | E121: =_xlfn.CONCAT(G121, " - ", F121) -> 2007 - 04 | F121: =TEXT(H121,"mm") -> 04 | G121: =TEXT(H121,"YYYY") -> 2007 | H121: 39187 | I121: 9299 | J121: =(I121-$AB$4) / $AB$8 -> -1.3716167 | K121: =IF(J121<=1, "<=1", IF(J121<=2, "<=2", IF(J121<=3, "<=3", "<=3"))) -> <=1 | N121: =IF(J121>=3, 3, IF(J121>=2, 2, IF(J121>=1, 1, IF(J121>=-2, -2, IF(J121>=-3, -3, "Error"))))) -> -2 | O121: 116 | P121: 12426 | X121: 2007 - 04 | Y121: 9299
A122: Pre-WebAnalytics | B122: =_xlfn.CONCAT(C122, " - ", A122) -> 0 - Pre-WebAnalytics | C122: 0 | D122: 121 | E122: =_xlfn.CONCAT(G122, " - ", F122) -> 2007 - 04 | F122: =TEXT(H122,"mm") -> 04 | G122: =TEXT(H122,"YYYY") -> 2007 | H122: 39194 | I122: 25516 | J122: =(I122-$AB$4) / $AB$8 -> 0.99911365 | K122: =IF(J122<=1, "<=1", IF(J122<=2, "<=2", IF(J122<=3, "<=3", "<=3"))) -> <=1 | L122: =COUNTA(K32:K122) -> 91 | M122: =L122/L172 -> #DIV/0! | N122: =IF(J122>=3, 3, IF(J122>=2, 2, IF(J122>=1, 1, IF(J122>=-2, -2, IF(J122>=-3, -3, "Error"))))) -> -2 | O122: 117 | P122: 32266 | X122: 2007 - 04 | Y122: 25516
A123: Pre-WebAnalytics | B123: =_xlfn.CONCAT(C123, " - ", A123) -> 0 - Pre-WebAnalytics | C123: 0 | D123: 122 | E123: =_xlfn.CONCAT(G123, " - ", F123) -> 2007 - 04 | F123: =TEXT(H123,"mm") -> 04 | G123: =TEXT(H123,"YYYY") -> 2007 | H123: 39201 | I123: 15326 | J123: =(I123-$AB$4) / $AB$8 -> -0.49054181 | K123: =IF(J123<=1, "<=1", IF(J123<=2, "<=2", IF(J123<=3, "<=3", "<=3"))) -> <=1 | N123: =IF(J123>=3, 3, IF(J123>=2, 2, IF(J123>=1, 1, IF(J123>=-2, -2, IF(J123>=-3, -3, "Error"))))) -> -2 | O123: 118 | P123: 21981 | X123: 2007 - 04 | Y123: 15326
A124: Pre-WebAnalytics | B124: =_xlfn.CONCAT(C124, " - ", A124) -> 0 - Pre-WebAnalytics | C124: 0 | D124: 123 | E124: =_xlfn.CONCAT(G124, " - ", F124) -> 2007 - 05 | F124: =TEXT(H124,"mm") -> 05 | G124: =TEXT(H124,"YYYY") -> 2007 | H124: 39208 | I124: 13354 | J124: =(I124-$AB$4) / $AB$8 -> -0.7788245 | K124: =IF(J124<=1, "<=1", IF(J124<=2, "<=2", IF(J124<=3, "<=3", "<=3"))) -> <=1 | N124: =IF(J124>=3, 3, IF(J124>=2, 2, IF(J124>=1, 1, IF(J124>=-2, -2, IF(J124>=-3, -3, "Error"))))) -> -2 | O124: 119 | P124: 12558 | X124: 2007 - 05 | Y124: 13354
A125: Pre-WebAnalytics | B125: =_xlfn.CONCAT(C125, " - ", A125) -> 0 - Pre-WebAnalytics | C125: 0 | D125: 124 | E125: =_xlfn.CONCAT(G125, " - ", F125) -> 2007 - 05 | F125: =TEXT(H125,"mm") -> 05 | G125: =TEXT(H125,"YYYY") -> 2007 | H125: 39215 | I125: 21417 | J125: =(I125-$AB$4) / $AB$8 -> 0.39988914 | K125: =IF(J125<=1, "<=1", IF(J125<=2, "<=2", IF(J125<=3, "<=3", "<=3"))) -> <=1 | N125: =IF(J125>=3, 3, IF(J125>=2, 2, IF(J125>=1, 1, IF(J125>=-2, -2, IF(J125>=-3, -3, "Error"))))) -> -2 | O125: 120 | P125: 9299 | X125: 2007 - 05 | Y125: 21417
A126: Pre-WebAnalytics | B126: =_xlfn.CONCAT(C126, " - ", A126) -> 0 - Pre-WebAnalytics | C126: 0 | D126: 125 | E126: =_xlfn.CONCAT(G126, " - ", F126) -> 2007 - 05 | F126: =TEXT(H126,"mm") -> 05 | G126: =TEXT(H126,"YYYY") -> 2007 | H126: 39222 | I126: 25529 | J126: =(I126-$AB$4) / $AB$8 -> 1.0010141 | K126: =IF(J126<=1, "<=1", IF(J126<=2, "<=2", IF(J126<=3, "<=3", "<=3"))) -> <=2 | N126: =IF(J126>=3, 3, IF(J126>=2, 2, IF(J126>=1, 1, IF(J126>=-2, -2, IF(J126>=-3, -3, "Error"))))) -> 1 | O126: 121 | P126: 25516 | X126: 2007 - 05 | Y126: 25529
A127: Pre-WebAnalytics | B127: =_xlfn.CONCAT(C127, " - ", A127) -> 0 - Pre-WebAnalytics | C127: 0 | D127: 126 | E127: =_xlfn.CONCAT(G127, " - ", F127) -> 2007 - 05 | F127: =TEXT(H127,"mm") -> 05 | G127: =TEXT(H127,"YYYY") -> 2007 | H127: 39229 | I127: 19585 | J127: =(I127-$AB$4) / $AB$8 -> 0.13207277 | K127: =IF(J127<=1, "<=1", IF(J127<=2, "<=2", IF(J127<=3, "<=3", "<=3"))) -> <=1 | N127: =IF(J127>=3, 3, IF(J127>=2, 2, IF(J127>=1, 1, IF(J127>=-2, -2, IF(J127>=-3, -3, "Error"))))) -> -2 | O127: 122 | P127: 15326 | X127: 2007 - 05 | Y127: 19585
...

Sheet DS_Financials
A1: Phase | B1: PhaseCode | C1: WeekCode | D1: MonthYear | E1: Year | F1: Week (2008-2009) | G1: Revenue | H1: Profit | I1: Lbs. Sold | J1: Inquiries
A2: Shakedown | B2: 1 | C2: 1 | D2: 05 | E2: 2008 | F2: May 25 - May 31 | G2: 480728.01 | H2: 118683.8 | I2: 16585.183 | J2: 13
A3: Shakedown | B3: 1 | C3: 2 | D3: 06 | E3: 2008 | F3: Jun 1 - Jun 7 | G3: 641155.48 | H3: 269604.7 | I3: 18906.38 | J3: 7
A4: Shakedown | B4: 1 | C4: 3 | D4: 06 | E4: 2008 | F4: Jun 8 - Jun 14 | G4: 890076.65 | H4: 275218.1 | I4: 28052.924 | J4: 5
A5: Shakedown | B5: 1 | C5: 4 | D5: 06 | E5: 2008 | F5: Jun 15 - Jun 21 | G5: 552673.98 | H5: 204153 | I5: 19382.312 | J5: 3
A6: Shakedown | B6: 1 | C6: 5 | D6: 06 | E6: 2008 | F6: Jun 22 - Jun 28 | G6: 750776.98 | H6: 256091.4 | I6: 24274.249 | J6: 3
A7: Shakedown | B7: 1 | C7: 6 | D7: 06 | E7: 2008 | F7: Jun 29 - Jul 5 | G7: 553054.69 | H7: 178134.5 | I7: 15308.721 | J7: 5
A8: Shakedown | B8: 1 | C8: 7 | D8: 07 | E8: 2008 | F8: Jul 6 - Jul 12 | G8: 274567.61 | H8: 62580.4 | I8: 8633.059 | J8: 16
A9: Shakedown | B9: 1 | C9: 8 | D9: 07 | E9: 2008 | F9: Jul 13 - Jul 19 | G9: 619284.64 | H9: 248458.4 | I9: 17216.342 | J9: 7
A10: Shakedown | B10: 1 | C10: 9 | D10: 07 | E10: 2008 | F10: Jul 20 - Jul 26 | G10: 674484.59 | H10: 238498.1 | I10: 17308.567 | J10: 6
A11: Shakedown | B11: 1 | C11: 10 | D11: 07 | E11: 2008 | F11: Jul 27 - Aug 2 | G11: 762559.12 | H11: 230237.8 | I11: 24571.171 | J11: 6
A12: Shakedown | B12: 1 | C12: 11 | D12: 08 | E12: 2008 | F12: Aug 3 - Aug 9 | G12: 479084.17 | H12: 156660.1 | I12: 14389.769 | J12: 4
A13: Shakedown | B13: 1 | C13: 12 | D13: 08 | E13: 2008 | F13: Aug 10 - Aug 16 | G13: 528270.72 | H13: 186775.6 | I13: 17230.826 | J13: 9
... A67: Post-Promo | B67: 4 | C67: 66 | D67: 08 | E67: 2009 | F67: Aug 23 - Aug 29 | G67: 615950.17 | H67: 206441.2 | I67: 23761.614 | J67: 8
G70: =MAX(I2:I67) -> 31968.976

Sheet Columbia CaseWorks
A1: Web Analytics at Quality Alloys, Inc.
A2: Author: | B2: Rob Weitz and David Rosenthal
A3: Columbia CaseWorks ID: 110203
F5: Copyright Information
F6: © 2010 by The Trustees of Columbia University in the City of New York. All rights reserved.
F7: Neither this spreadsheet nor the associated case can be used or reproduced
A8: Abstract: | F8: without explicit permission from Columbia CaseWorks.
A9: This spreadsheet accompanies the Web Analytics at Quality Alloys, Inc case. | F9: To obtain permission, please visit:
F10: www.gsb.columbia.edu/CaseWorks
F11: or e-mail:
F12: ColumbiaCaseWorks@gsb.columbia.edu

Sheet Weekly Visits
A1: Quality Alloys
A2: Weekly Web Analytics | E2: Initial "Shakedown" Period | H2: Pre and Post Promotion Periods
A3: May 25, 2008 - August 29, 2009 | E3: Promotion Period | H3: are unshaded.
J4: Bounce Rate is defined as the percentage of visitors who leave a webpage without taking any action, such as clicking on a link, filling out a form, or making a purchase. Essentially, it measures how many visitors “bounce” away after viewing only one page without engaging further with the site1. A high bounce rate can indicate issues with content, user experience, page layout, or copywriting. For example, if a visitor lands on a page and immediately leaves without interacting further, that contributes to the bounce rate. In Google Analytics, bounce rate is calculated as:
A5: Week (2008-2009) | B5: Visits | C5: Unique Visits | D5: Pageviews | E5: Pages/Visit | F5: Avg. Time on Site (secs.) | G5: Bounce Rate | H5: % New Visits
A6: May 25 - May 31 | B6: 1632 | C6: 1509 | D6: 3328 | E6: 2.04 | F6: 71 | G6: 0.7267 | H6: 0.8854 | J6: Bounce Rate=Total Number of SessionsSingle-Page Sessions​×100
A7: Jun 1 - Jun 7 | B7: 1580 | C7: 1450 | D7: 3097 | E7: 1.96 | F7: 56 | G7: 0.7551 | H7: 0.8734
A8: Jun 8 - Jun 14 | B8: 1441 | C8: 1306 | D8: 3202 | E8: 2.22 | F8: 79 | G8: 0.7398 | H8: 0.8432 | J8: The average bounce rate varies by industry and traffic sources. While an average range of 41% to 51% is common, specific benchmarks depend on your website type and where your traffic comes from. For instance, e-commerce sites tend to have lower bounce rates (20% to 45%), while blogs may have higher rates (up to 90%)1. Keep in mind that context matters, and comparing your site’s bounce rate to similar sites in your category provides a more meaningful assessmen
A9: Jun 15 - Jun 21 | B9: 1452 | C9: 1301 | D9: 3170 | E9: 2.18 | F9: 81 | G9: 0.7362 | H9: 0.8437
A10: Jun 22 - Jun 28 | B10: 1339 | C10: 1255 | D10: 2366 | E10: 1.77 | F10: 50 | G10: 0.764 | H10: 0.8925
A11: Jun 29 - Jul 5 | B11: 892 | C11: 841 | D11: 1865 | E11: 2.09 | F11: 71 | G11: 0.7365 | H11: 0.8756
A12: Jul 6 - Jul 12 | B12: 797 | C12: 731 | D12: 1885 | E12: 2.37 | F12: 80 | G12: 0.6148 | H12: 0.857
A13: Jul 13 - Jul 19 | B13: 744 | C13: 706 | D13: 1916 | E13: 2.58 | F13: 96 | G13: 0.5927 | H13: 0.8884
A14: Jul 20 - Jul 26 | B14: 1044 | C14: 976 | D14: 2670 | E14: 2.56 | F14: 82 | G14: 0.6034 | H14: 0.8669
A15: Jul 27 - Aug 2 | B15: 906 | C15: 850 | D15: 2189 | E15: 2.42 | F15: 78 | G15: 0.6336 | H15: 0.8742
A16: Aug 3 - Aug 9 | B16: 849 | C16: 791 | D16: 1947 | E16: 2.29 | F16: 91 | G16: 0.6443 | H16: 0.8704
A17: Aug 10 - Aug 16 | B17: 737 | C17: 685 | D17: 1746 | E17: 2.37 | F17: 98 | G17: 0.6282 | H17: 0.8725
A18: Aug 17 - Aug 23 | B18: 734 | C18: 668 | D18: 1946 | E18: 2.65 | F18: 100 | G18: 0.624 | H18: 0.8433
A19: Aug 24 - Aug 30 | B19: 626 | C19: 594 | D19: 1540 | E19: 2.46 | F19: 91 | G19: 0.6198 | H19: 0.8658
A20: Aug 31 - Sep 6 | B20: 577 | C20: 537 | D20: 1489 | E20: 2.58 | F20: 83 | G20: 0.6205 | H20: 0.8666
... A71: Aug 23 - Aug 29 | B71: 772 | C71: 709 | D71: 1767 | E71: 2.29 | F71: 72 | G71: 0.6192 | H71: 0.8523

Sheet Financials
A1: Quality Alloys
A2: Weekly Financial Data | C2: Initial "Shakedown" Period | F2: Pre and Post Promotion Periods
A3: May 25, 2008 - August 29, 2009 | C3: Promotion Period | F3: are unshaded.
A5: Week (2008-2009) | B5: Revenue | C5: Profit | D5: Lbs. Sold | E5: Inquiries
A6: May 25 - May 31 | B6: 480728.01 | C6: 118683.8 | D6: 16585.183 | E6: 13
A7: Jun 1 - Jun 7 | B7: 641155.48 | C7: 269604.7 | D7: 18906.38 | E7: 7
A8: Jun 8 - Jun 14 | B8: 890076.65 | C8: 275218.1 | D8: 28052.924 | E8: 5
A9: Jun 15 - Jun 21 | B9: 552673.98 | C9: 204153 | D9: 19382.312 | E9: 3
A10: Jun 22 - Jun 28 | B10: 750776.98 | C10: 256091.4 | D10: 24274.249 | E10: 3
A11: Jun 29 - Jul 5 | B11: 553054.69 | C11: 178134.5 | D11: 15308.721 | E11: 5
A12: Jul 6 - Jul 12 | B12: 274567.61 | C12: 62580.4 | D12: 8633.059 | E12: 16
A13: Jul 13 - Jul 19 | B13: 619284.64 | C13: 248458.4 | D13: 17216.342 | E13: 7
A14: Jul 20 - Jul 26 | B14: 674484.59 | C14: 238498.1 | D14: 17308.567 | E14: 6
A15: Jul 27 - Aug 2 | B15: 762559.12 | C15: 230237.8 | D15: 24571.171 | E15: 6
A16: Aug 3 - Aug 9 | B16: 479084.17 | C16: 156660.1 | D16: 14389.769 | E16: 4
A17: Aug 10 - Aug 16 | B17: 528270.72 | C17: 186775.6 | D17: 17230.826 | E17: 9
... A71: Aug 23 - Aug 29 | B71: 615950.17 | C71: 206441.2 | D71: 23761.614 | E71: 8
D74: =MAX(D6:D71) -> 31968.976

Sheet Lbs. Sold
A1: Quality Alloys
A2: Lbs. of Material Sold Per Week
A3: Week of Jan. 3, 2005 through week of July 19, 2010.
A5: Week | B5: Lbs. Sold
A6: 38354 | B6: 23662
A7: 38361 | B7: 12699
A8: 38368 | B8: 23095
A9: 38375 | B9: 27944
A10: 38382 | B10: 20516
A11: 38389 | B11: 25546
A12: 38396 | B12: 20023
A13: 38403 | B13: 35247
A14: 38410 | B14: 23615
A15: 38417 | B15: 16655
A16: 38424 | B16: 14748
A17: 38431 | B17: 18159
... A295: 40377 | B295: 14307

Sheet Daily Visits
A1: Day | B1: Visits | C1: z-score | D1: Count | G1: Count | H1: Visits | L1: Row Labels | M1: Count of Count
A2: Sunday, January 11, 2009 | B2: 37 | C2: =(B2-$I$3)/$I$7 -> -1.1539588 | D2: =IF(C2<=1, "<=1", IF(C2<=2, "<=2", IF(C2<=3, "<=3", "<=3"))) -> <=1 | E2: =COUNTA(D2:D416) -> 415 | F2: =1-(E2/462) -> 0.1017316 | G2: =IF(C2>=3, 3, IF(C2>=2, 2, IF(C2>=1, 1, IF(C2>=-2, -2, IF(C2>=-3, -3, "Error"))))) -> -2 | L2: -2 | M2: 415
A3: Sunday, November 2, 2008 | B3: 39 | C3: =(B3-$I$3)/$I$7 -> -1.1335859 | D3: =IF(C3<=1, "<=1", IF(C3<=2, "<=2", IF(C3<=3, "<=3", "<=3"))) -> <=1 | G3: =IF(C3>=3, 3, IF(C3>=2, 2, IF(C3>=1, 1, IF(C3>=-2, -2, IF(C3>=-3, -3, "Error"))))) -> -2 | H3: Mean | I3: 150.28355 | L3: 1 | M3: 24
A4: Friday, December 26, 2008 | B4: 41 | C4: =(B4-$I$3)/$I$7 -> -1.113213 | D4: =IF(C4<=1, "<=1", IF(C4<=2, "<=2", IF(C4<=3, "<=3", "<=3"))) -> <=1 | G4: =IF(C4>=3, 3, IF(C4>=2, 2, IF(C4>=1, 1, IF(C4>=-2, -2, IF(C4>=-3, -3, "Error"))))) -> -2 | H4: Standard Error | I4: 4.5672581 | L4: 2 | M4: 9
A5: Saturday, December 13, 2008 | B5: 44 | C5: =(B5-$I$3)/$I$7 -> -1.0826536 | D5: =IF(C5<=1, "<=1", IF(C5<=2, "<=2", IF(C5<=3, "<=3", "<=3"))) -> <=1 | G5: =IF(C5>=3, 3, IF(C5>=2, 2, IF(C5>=1, 1, IF(C5>=-2, -2, IF(C5>=-3, -3, "Error"))))) -> -2 | H5: Median | I5: 122 | L5: 3 | M5: 14
A6: Saturday, October 18, 2008 | B6: 46 | C6: =(B6-$I$3)/$I$7 -> -1.0622806 | D6: =IF(C6<=1, "<=1", IF(C6<=2, "<=2", IF(C6<=3, "<=3", "<=3"))) -> <=1 | G6: =IF(C6>=3, 3, IF(C6>=2, 2, IF(C6>=1, 1, IF(C6>=-2, -2, IF(C6>=-3, -3, "Error"))))) -> -2 | H6: Mode | I6: 91 | L6: (blank)
A7: Saturday, December 27, 2008 | B7: 46 | C7: =(B7-$I$3)/$I$7 -> -1.0622806 | D7: =IF(C7<=1, "<=1", IF(C7<=2, "<=2", IF(C7<=3, "<=3", "<=3"))) -> <=1 | G7: =IF(C7>=3, 3, IF(C7>=2, 2, IF(C7>=1, 1, IF(C7>=-2, -2, IF(C7>=-3, -3, "Error"))))) -> -2 | H7: Standard Deviation | I7: 98.169492 | L7: Grand Total | M7: 462
A8: Sunday, October 26, 2008 | B8: 47 | C8: =(B8-$I$3)/$I$7 -> -1.0520942 | D8: =IF(C8<=1, "<=1", IF(C8<=2, "<=2", IF(C8<=3, "<=3", "<=3"))) -> <=1 | G8: =IF(C8>=3, 3, IF(C8>=2, 2, IF(C8>=1, 1, IF(C8>=-2, -2, IF(C8>=-3, -3, "Error"))))) -> -2 | H8: Sample Variance | I8: 9637.2491
A9: Saturday, November 1, 2008 | B9: 47 | C9: =(B9-$I$3)/$I$7 -> -1.0520942 | D9: =IF(C9<=1, "<=1", IF(C9<=2, "<=2", IF(C9<=3, "<=3", "<=3"))) -> <=1 | G9: =IF(C9>=3, 3, IF(C9>=2, 2, IF(C9>=1, 1, IF(C9>=-2, -2, IF(C9>=-3, -3, "Error"))))) -> -2 | H9: Kurtosis | I9: 5.8619896
A10: Saturday, November 15, 2008 | B10: 47 | C10: =(B10-$I$3)/$I$7 -> -1.0520942 | D10: =IF(C10<=1, "<=1", IF(C10<=2, "<=2", IF(C10<=3, "<=3", "<=3"))) -> <=1 | G10: =IF(C10>=3, 3, IF(C10>=2, 2, IF(C10>=1, 1, IF(C10>=-2, -2, IF(C10>=-3, -3, "Error"))))) -> -2 | H10: Skewness | I10: 2.1669722
A11: Sunday, November 9, 2008 | B11: 48 | C11: =(B11-$I$3)/$I$7 -> -1.0419077 | D11: =IF(C11<=1, "<=1", IF(C11<=2, "<=2", IF(C11<=3, "<=3", "<=3"))) -> <=1 | G11: =IF(C11>=3, 3, IF(C11>=2, 2, IF(C11>=1, 1, IF(C11>=-2, -2, IF(C11>=-3, -3, "Error"))))) -> -2 | H11: Range | I11: 627
A12: Saturday, September 13, 2008 | B12: 49 | C12: =(B12-$I$3)/$I$7 -> -1.0317212 | D12: =IF(C12<=1, "<=1", IF(C12<=2, "<=2", IF(C12<=3, "<=3", "<=3"))) -> <=1 | G12: =IF(C12>=3, 3, IF(C12>=2, 2, IF(C12>=1, 1, IF(C12>=-2, -2, IF(C12>=-3, -3, "Error"))))) -> -2 | H12: Minimum | I12: 37
A13: Sunday, December 21, 2008 | B13: 49 | C13: =(B13-$I$3)/$I$7 -> -1.0317212 | D13: =IF(C13<=1, "<=1", IF(C13<=2, "<=2", IF(C13<=3, "<=3", "<=3"))) -> <=1 | G13: =IF(C13>=3, 3, IF(C13>=2, 2, IF(C13>=1, 1, IF(C13>=-2, -2, IF(C13>=-3, -3, "Error"))))) -> -2 | H13: Maximum | I13: 664
A14: Friday, January 2, 2009 | B14: 49 | C14: =(B14-$I$3)/$I$7 -> -1.0317212 | D14: =IF(C14<=1, "<=1", IF(C14<=2, "<=2", IF(C14<=3, "<=3", "<=3"))) -> <=1 | G14: =IF(C14>=3, 3, IF(C14>=2, 2, IF(C14>=1, 1, IF(C14>=-2, -2, IF(C14>=-3, -3, "Error"))))) -> -2 | H14: Sum | I14: 69431
A15: Saturday, September 20, 2008 | B15: 50 | C15: =(B15-$I$3)/$I$7 -> -1.0215348 | D15: =IF(C15<=1, "<=1", IF(C15<=2, "<=2", IF(C15<=3, "<=3", "<=3"))) -> <=1 | G15: =IF(C15>=3, 3, IF(C15>=2, 2, IF(C15>=1, 1, IF(C15>=-2, -2, IF(C15>=-3, -3, "Error"))))) -> -2 | H15: Count | I15: 462
A16: Sunday, January 4, 2009 | B16: 50 | C16: =(B16-$I$3)/$I$7 -> -1.0215348 | D16: =IF(C16<=1, "<=1", IF(C16<=2, "<=2", IF(C16<=3, "<=3", "<=3"))) -> <=1 | G16: =IF(C16>=3, 3, IF(C16>=2, 2, IF(C16>=1, 1, IF(C16>=-2, -2, IF(C16>=-3, -3, "Error"))))) -> -2 | H16: Confidence Level(95%) | I16: 8.9752246
A17: Sunday, October 5, 2008 | B17: 51 | C17: =(B17-$I$3)/$I$7 -> -1.0113483 | D17: =IF(C17<=1, "<=1", IF(C17<=2, "<=2", IF(C17<=3, "<=3", "<=3"))) -> <=1 | G17: =IF(C17>=3, 3, IF(C17>=2, 2, IF(C17>=1, 1, IF(C17>=-2, -2, IF(C17>=-3, -3, "Error"))))) -> -2
A18: Sunday, October 12, 2008 | B18: 51 | C18: =(B18-$I$3)/$I$7 -> -1.0113483 | D18: =IF(C18<=1, "<=1", IF(C18<=2, "<=2", IF(C18<=3, "<=3", "<=3"))) -> <=1 | G18: =IF(C18>=3, 3, IF(C18>=2, 2, IF(C18>=1, 1, IF(C18>=-2, -2, IF(C18>=-3, -3, "Error"))))) -> -2
A19: Saturday, November 8, 2008 | B19: 51 | C19: =(B19-$I$3)/$I$7 -> -1.0113483 | D19: =IF(C19<=1, "<=1", IF(C19<=2, "<=2", IF(C19<=3, "<=3", "<=3"))) -> <=1 | G19: =IF(C19>=3, 3, IF(C19>=2, 2, IF(C19>=1, 1, IF(C19>=-2, -2, IF(C19>=-3, -3, "Error"))))) -> -2
A20: Saturday, November 22, 2008 | B20: 51 | C20: =(B20-$I$3)/$I$7 -> -1.0113483 | D20: =IF(C20<=1, "<=1", IF(C20<=2, "<=2", IF(C20<=3, "<=3", "<=3"))) -> <=1 | G20: =IF(C20>=3, 3, IF(C20>=2, 2, IF(C20>=1, 1, IF(C20>=-2, -2, IF(C20>=-3, -3, "Error"))))) -> -2
A21: Sunday, September 21, 2008 | B21: 52 | C21: =(B21-$I$3)/$I$7 -> -1.0011618 | D21: =IF(C21<=1, "<=1", IF(C21<=2, "<=2", IF(C21<=3, "<=3", "<=3"))) -> <=1 | G21: =IF(C21>=3, 3, IF(C21>=2, 2, IF(C21>=1, 1, IF(C21>=-2, -2, IF(C21>=-3, -3, "Error"))))) -> -2
A22: Sunday, November 16, 2008 | B22: 52 | C22: =(B22-$I$3)/$I$7 -> -1.0011618 | D22: =IF(C22<=1, "<=1", IF(C22<=2, "<=2", IF(C22<=3, "<=3", "<=3"))) -> <=1 | G22: =IF(C22>=3, 3, IF(C22>=2, 2, IF(C22>=1, 1, IF(C22>=-2, -2, IF(C22>=-3, -3, "Error"))))) -> -2
A23: Sunday, December 7, 2008 | B23: 52 | C23: =(B23-$I$3)/$I$7 -> -1.0011618 | D23: =IF(C23<=1, "<=1", IF(C23<=2, "<=2", IF(C23<=3, "<=3", "<=3"))) -> <=1 | G23: =IF(C23>=3, 3, IF(C23>=2, 2, IF(C23>=1, 1, IF(C23>=-2, -2, IF(C23>=-3, -3, "Error"))))) -> -2
A24: Saturday, January 10, 2009 | B24: 52 | C24: =(B24-$I$3)/$I$7 -> -1.0011618 | D24: =IF(C24<=1, "<=1", IF(C24<=2, "<=2", IF(C24<=3, "<=3", "<=3"))) -> <=1 | G24: =IF(C24>=3, 3, IF(C24>=2, 2, IF(C24>=1, 1, IF(C24>=-2, -2, IF(C24>=-3, -3, "Error"))))) -> -2
A25: Saturday, October 11, 2008 | B25: 53 | C25: =(B25-$I$3)/$I$7 -> -0.99097538 | D25: =IF(C25<=1, "<=1", IF(C25<=2, "<=2", IF(C25<=3, "<=3", "<=3"))) -> <=1 | G25: =IF(C25>=3, 3, IF(C25>=2, 2, IF(C25>=1, 1, IF(C25>=-2, -2, IF(C25>=-3, -3, "Error"))))) -> -2
A26: Saturday, October 25, 2008 | B26: 53 | C26: =(B26-$I$3)/$I$7 -> -0.99097538 | D26: =IF(C26<=1, "<=1", IF(C26<=2, "<=2", IF(C26<=3, "<=3", "<=3"))) -> <=1 | G26: =IF(C26>=3, 3, IF(C26>=2, 2, IF(C26>=1, 1, IF(C26>=-2, -2, IF(C26>=-3, -3, "Error"))))) -> -2
A27: Saturday, November 29, 2008 | B27: 53 | C27: =(B27-$I$3)/$I$7 -> -0.99097538 | D27: =IF(C27<=1, "<=1", IF(C27<=2, "<=2", IF(C27<=3, "<=3", "<=3"))) -> <=1 | G27: =IF(C27>=3, 3, IF(C27>=2, 2, IF(C27>=1, 1, IF(C27>=-2, -2, IF(C27>=-3, -3, "Error"))))) -> -2
A28: Saturday, December 6, 2008 | B28: 53 | C28: =(B28-$I$3)/$I$7 -> -0.99097538 | D28: =IF(C28<=1, "<=1", IF(C28<=2, "<=2", IF(C28<=3, "<=3", "<=3"))) -> <=1 | G28: =IF(C28>=3, 3, IF(C28>=2, 2, IF(C28>=1, 1, IF(C28>=-2, -2, IF(C28>=-3, -3, "Error"))))) -> -2
... A416: Monday, May 4, 2009 | B416: 248 | C416: =(B416-$I$3)/$I$7 -> 0.99538511 | D416: =IF(C416<=1, "<=1", IF(C416<=2, "<=2", IF(C416<=3, "<=3", "<=3"))) -> <=1 | G416: =IF(C416>=3, 3, IF(C416>=2, 2, IF(C416>=1, 1, IF(C416>=-2, -2, IF(C416>=-3, -3, "Error"))))) -> -2
A417: Monday, March 30, 2009 | B417: 251 | C417: =(B417-$I$3)/$I$7 -> 1.0259445 | D417: =IF(C417<=1, "<=1", IF(C417<=2, "<=2", IF(C417<=3, "<=3", "<=3"))) -> <=2 | E417: =COUNTA(D417:D440) -> 24 | F417: =1-(E417/462) -> 0.94805195 | G417: =IF(C417>=3, 3, IF(C417>=2, 2, IF(C417>=1, 1, IF(C417>=-2, -2, IF(C417>=-3, -3, "Error"))))) -> 1
A418: Wednesday, June 4, 2008 | B418: 252 | C418: =(B418-$I$3)/$I$7 -> 1.036131 | D418: =IF(C418<=1, "<=1", IF(C418<=2, "<=2", IF(C418<=3, "<=3", "<=3"))) -> <=2 | G418: =IF(C418>=3, 3, IF(C418>=2, 2, IF(C418>=1, 1, IF(C418>=-2, -2, IF(C418>=-3, -3, "Error"))))) -> 1
A419: Thursday, April 2, 2009 | B419: 253 | C419: =(B419-$I$3)/$I$7 -> 1.0463174 | D419: =IF(C419<=1, "<=1", IF(C419<=2, "<=2", IF(C419<=3, "<=3", "<=3"))) -> <=2 | G419: =IF(C419>=3, 3, IF(C419>=2, 2, IF(C419>=1, 1, IF(C419>=-2, -2, IF(C419>=-3, -3, "Error"))))) -> 1
A420: Sunday, February 8, 2009 | B420: 262 | C420: =(B420-$I$3)/$I$7 -> 1.1379956 | D420: =IF(C420<=1, "<=1", IF(C420<=2, "<=2", IF(C420<=3, "<=3", "<=3"))) -> <=2 | G420: =IF(C420>=3, 3, IF(C420>=2, 2, IF(C420>=1, 1, IF(C420>=-2, -2, IF(C420>=-3, -3, "Error"))))) -> 1
A421: Thursday, May 29, 2008 | B421: 263 | C421: =(B421-$I$3)/$I$7 -> 1.1481821 | D421: =IF(C421<=1, "<=1", IF(C421<=2, "<=2", IF(C421<=3, "<=3", "<=3"))) -> <=2 | G421: =IF(C421>=3, 3, IF(C421>=2, 2, IF(C421>=1, 1, IF(C421>=-2, -2, IF(C421>=-3, -3, "Error"))))) -> 1
A422: Tuesday, March 31, 2009 | B422: 267 | C422: =(B422-$I$3)/$I$7 -> 1.1889279 | D422: =IF(C422<=1, "<=1", IF(C422<=2, "<=2", IF(C422<=3, "<=3", "<=3"))) -> <=2 | G422: =IF(C422>=3, 3, IF(C422>=2, 2, IF(C422>=1, 1, IF(C422>=-2, -2, IF(C422>=-3, -3, "Error"))))) -> 1
A423: Thursday, April 30, 2009 | B423: 271 | C423: =(B423-$I$3)/$I$7 -> 1.2296738 | D423: =IF(C423<=1, "<=1", IF(C423<=2, "<=2", IF(C423<=3, "<=3", "<=3"))) -> <=2 | G423: =IF(C423>=3, 3, IF(C423>=2, 2, IF(C423>=1, 1, IF(C423>=-2, -2, IF(C423>=-3, -3, "Error"))))) -> 1
A424: Tuesday, February 17, 2009 | B424: 276 | C424: =(B424-$I$3)/$I$7 -> 1.2806061 | D424: =IF(C424<=1, "<=1", IF(C424<=2, "<=2", IF(C424<=3, "<=3", "<=3"))) -> <=2 | G424: =IF(C424>=3, 3, IF(C424>=2, 2, IF(C424>=1, 1, IF(C424>=-2, -2, IF(C424>=-3, -3, "Error"))))) -> 1
A425: Monday, February 16, 2009 | B425: 277 | C425: =(B425-$I$3)/$I$7 -> 1.2907926 | D425: =IF(C425<=1, "<=1", IF(C425<=2, "<=2", IF(C425<=3, "<=3", "<=3"))) -> <=2 | G425: =IF(C425>=3, 3, IF(C425>=2, 2, IF(C425>=1, 1, IF(C425>=-2, -2, IF(C425>=-3, -3, "Error"))))) -> 1
A426: Wednesday, May 28, 2008 | B426: 282 | C426: =(B426-$I$3)/$I$7 -> 1.3417249 | D426: =IF(C426<=1, "<=1", IF(C426<=2, "<=2", IF(C426<=3, "<=3", "<=3"))) -> <=2 | G426: =IF(C426>=3, 3, IF(C426>=2, 2, IF(C426>=1, 1, IF(C426>=-2, -2, IF(C426>=-3, -3, "Error"))))) -> 1
A427: Friday, May 1, 2009 | B427: 283 | C427: =(B427-$I$3)/$I$7 -> 1.3519113 | D427: =IF(C427<=1, "<=1", IF(C427<=2, "<=2", IF(C427<=3, "<=3", "<=3"))) -> <=2 | G427: =IF(C427>=3, 3, IF(C427>=2, 2, IF(C427>=1, 1, IF(C427>=-2, -2, IF(C427>=-3, -3, "Error"))))) -> 1
...

Sheet Demographics
A1: Quality Alloys
A2: Source and Other Data
A3: May 25, 2008 - August 29, 2009
A6: 1) | B6: All Traffic Sources
C7: Visits
B8: Referring Sites | C8: 38754
B9: Search Engines | C9: 20964
B10: Direct Traffic | C10: 9709
B11: Other | C11: 4
A13: 2) | B13: Top Ten Referring Sites
C14: Visits
B15: psicofxp.com | C15: 310
B16: mail.google.com | C16: 337
B17: mu.com | C17: 344
B18: thomasnet.com | C18: 379
B19: freepatentsonline.com | C19: 389
B20: searchportal.information.com | C20: 582
B21: globalspec.com | C21: 693
B22: sedoparking.com | C22: 3138
B23: pagead2.googlesyndication.com | C23: 8044 | D23: =C23+C24 -> 23670 | E23: =D23/SUM(C15:C24) -> 0.7931774
B24: googleads.g.doubleclick.net | C24: 15626
A26: 3) | B26: Top Ten Search Engine Sources of Visits
C27: Visits
B28: google | C28: 17681
B29: yahoo | C29: 1250
B30: search | C30: 592
